Workbook

Sheet 🗂️ Configuración
A1: 🗂️ EXPEDIENTE DEL DETECTIVE — Datos del Agente
A3: Completa tus datos antes de empezar el caso. Esto identifica tu trabajo para tu profesor(a).
B4: Nombre completo
B5: DNI
B6: Grado y sección
B8: Curso | C8: EST1_2026
B9: Notebook | C9: sheets_caso1_semana1
A10: (Curso y Notebook son fijos — identifican este caso para la base de datos. No los edites.)
A12: =IF(AND(C4<>"",C5<>"",C6<>""),"✅ Listo, agente. Puedes ir a la pestaña 🧩 Tu Caso.","⚠️ Falta completar Nombre, DNI o Grado antes de empezar.") -> ⚠️ Falta completar Nombre, DNI o Grado antes de empezar.

Sheet 📁 Instrucciones
A1: 🕵️ CASO N.º 1 — Abriendo el Caso — Semana 1
A4: "Dos tesoreros de la Kermés cuentan el mismo montón de boletos vendidos. Uno dice que se vendieron 68. El otro dice 60. Ninguno mintió, ninguno se equivocó al sumar. ¿Cómo es posible?"
A6: "Te acaba de llegar el primer caso de la Agencia. La evidencia está desordenada, con duplicados, ventas canceladas y espacios vacíos — antes de poder calcular nada con confianza, tu primer trabajo como detective es poner la evidencia en orden."
A8: "Al final de hoy vas a confiar en cuántos boletos se vendieron cada día. El total general te lo confirma la próxima sesión con una fórmula nueva."
A11: 🪜 Los 4 pasos de esta sesión
A12: 1. Revisar la evidencia — mirar el expediente crudo, tal como llegó (pestaña 📊 Datos).
A13: 2. Limpiar el caso — arreglar duplicados, texto inconsistente y datos faltantes.
A14: 3. Filtrar por día — aislar solo la evidencia de un día y leer el subtotal.
A15: 4. Reto bonus — un desafío extra, sin fórmulas nuevas.
A17: 🕹️ Cómo funciona esta hoja
A18: • Empieza en 🗂️ Configuración y escribe tu nombre, DNI y grado.
A19: • La pestaña 📊 Datos es tu expediente — ahí edita, borra filas y aplica filtros.
... A22: • Algunas tareas (como dar formato) las revisa tu profesor(a) — ahí verás una casilla en vez de una respuesta.

Sheet 🔎 Ejemplo Resuelto
A1: 🔎 Ejemplo Resuelto
A4: 🗣️ Preguntas guía — para conversar en clase (no se califica)
A5: 1 | B5: ¿Cuántas filas hay en total? ¿Todas son ventas reales?
A6: 2 | B6: Miren la fila de Milagros Guerra — ¿por qué no deberíamos contarla?
A7: 3 | B7: Tomás Effio aparece dos veces con exactamente los mismos datos — ¿qué significa eso?
A8: 4 | B8: La columna Día tiene 'Viernes', 'viernes' y 'VIERNES' — ¿son iguales para una computadora?
A9: 5 | B9: Nadia Chumpitaz no tiene número de Boletos — ¿qué deberíamos hacer antes de asumir un valor?
A10: 6 | B10: Si aplicamos un filtro para ver solo 'Sábado', ¿qué le pasa a las demás filas: desaparecen o solo se esconden?
A12: 🗂️ Evidencia de ejemplo — El Bazar Escolar
A13: Comprador | B13: Boletos | C13: Día | D13: Estado
A14: Tomás Effio | B14: 4 | C14: Viernes | D14: Válido
A15: Lucía Bravo | B15: 3 | C15: sábado | D15: Válido
A16: Ricardo Soto | B16: 5 | C16: VIERNES | D16: Válido
A17: Nadia Chumpitaz | C17: Sábado | D17: Válido
A18: Bruno Alania | B18: 4 | C18: viernes | D18: Válido
A19: Ximena Delgado | B19: 3 | C19: Sábado | D19: Válido
A20: Tomás Effio | B20: 4 | C20: Viernes | D20: Válido
A21: Milagros Guerra | B21: 12 | C21: Sábado | D21: Cancelado

Sheet 📊 Datos
A1: 📊 EXPEDIENTE — Evidencia Cruda del Caso 1
A3: Esta es tu área de trabajo: edita, borra filas y aplica filtros aquí directamente. Tus respuestas en 🧩 Tu Caso se revisan contra lo que hagas en esta pestaña.
A4: Comprador | B4: Boletos | C4: Día | D4: Estado
A5: Bruno Alania | C5: SABADO | D5: Válido
A6: Sebastián Cusicanqui | B6: 6 | C6: viernes | D6: Válido
A7: Camila Chumpitaz | C7: SABADO | D7: Válido
A8: María Palomino | C8: Sábado | D8: Válido
A9: Ximena Mamani | B9: 3 | C9: VIERNES | D9: Válido
A10: Joaquín Bravo | B10: 4 | C10: VIERNES | D10: Válido
A11: Andrés Mamani | B11: 4 | C11: Viernes | D11: Válido
A12: Luis Huamán | C12: Viernes | D12: Válido
A13: Diego Cusicanqui | B13: 3 | C13: Viernes | D13: Válido
A14: Valeria Zevallos | B14: 13 | C14: SÁBADO | D14: Cancelado
A15: Gabriela Salas | C15: VIERNES | D15: Válido
A16: Valeria Soto | B16: 4 | C16: viernes | D16: Válido
A17: Ana Quispe | B17: 3 | C17: SABADO | D17: Válido
A18: Luis Vargas | B18: 6 | C18: sabado | D18: Válido
A19: Lucía Flores | B19: 4 | C19: Viernes | D19: Válido
A20: Iván Mamani | B20: 3 | C20: sabado | D20: Válido
A21: Milagros Paz | B21: 3 | C21: Viernes | D21: Válido
A22: Milagros Bravo | B22: 4 | C22: sabado | D22: Válido
A23: Sofía Mamani | B23: 6 | C23: sabado | D23: Válido
A24: Mateo Delgado | B24: 2 | C24: viernes | D24: Válido
A25: Ximena Soto | B25: 2 | C25: VIERNES | D25: Válido
A26: Sebastián Cusi | C26: Viernes | D26: Válido
A27: Camila Huamán | B27: 6 | C27: Sábado | D27: Válido
A28: Tomás Rojas | B28: 2 | C28: Viernes | D28: Válido
A29: Joaquín Bravo | B29: 4 | C29: VIERNES | D29: Válido
A30: Valeria Flores | B30: 5 | C30: Viernes | D30: Válido
A31: Ana Alania | B31: 4 | C31: VIERNES | D31: Válido
A32: Ricardo Bravo | B32: 2 | C32: VIERNES | D32: Válido
A33: Sebastián Flores | B33: 4 | C33: SÁBADO | D33: Válido
A34: Rosa Torres | B34: 5 | C34: Viernes | D34: Válido
A35: Iván Rojas | B35: 6 | C35: Sábado | D35: Válido
A36: Fernando Huamán | B36: 3 | C36: SABADO | D36: Válido
A37: Estefanía Ninahuanca | B37: 5 | C37: Viernes | D37: Válido
A38: Lucía Mamani | C38: viernes | D38: Válido
A39: Milagros Flores | B39: 2 | C39: Sábado | D39: Válido
A40: Milagros Guerra | B40: 2 | C40: Viernes | D40: Válido
A41: Lucía Contreras | B41: 2 | C41: Viernes | D41: Válido
...

Sheet 🧩 Tu Caso
A1: 🧩 CASO N.º 1 — Tu Expediente de Trabajo | G1: ⚡ XP TOTAL
G2: =B67 -> 0
A4: =IF(AND('🗂️ Configuración'!C4<>"",'🗂️ Configuración'!C5<>"",'🗂️ Configuración'!C6<>""),"✅ Expediente identificado: "&'🗂️ Configuración'!C4&" — puedes empezar.","⚠️ Ve a 🗂️ Configuración y completa tu nombre, DNI y grado antes de empezar.") -> ⚠️ Ve a 🗂️ Configuración y completa tu nombre, DNI y grado antes de empezar.
A6: 🔎 SECCIÓN 1 — Revisar la Evidencia (20 XP)
A7: Clave | B7: Instrucción | C7: Tu respuesta | D7: Resultado
A8: ex1 | B8: Sin editar nada todavía: ve a 📊 Datos y cuenta — ¿cuántas filas de evidencia llegaron? (no cuentes el encabezado) (+5 XP) | D8: =IF(C8="","–",IF(IFERROR(VALUE(C8)='🔒 Clave'!B2,FALSE),"✓ +5 XP","✗ revisa")) -> – | E8: =IF(LEFT(D8,1)="✓",5,0) -> 0
A9: ex2 | B9: ¿Cuántas columnas/pistas tiene el caso? (+5 XP) | D9: =IF(C9="","–",IF(IFERROR(VALUE(C9)='🔒 Clave'!B3,FALSE),"✓ +5 XP","✗ revisa")) -> – | E9: =IF(LEFT(D9,1)="✓",5,0) -> 0
A10: t1 | B10: En 📊 Datos, cada FILA representa: a) una columna de datos, b) un boleto vendido (una pieza de evidencia), c) el nombre de la Agencia, d) el precio total (+5 XP) | D10: =IF(C10="","–",IF(IFERROR(EXACT(LOWER(C10),LOWER('🔒 Clave'!B5)),FALSE),"✓ +5 XP","✗ revisa")) -> – | E10: =IF(LEFT(D10,1)="✓",5,0) -> 0
A11: debug1 | B11: Un compañero ficticio contó 109 filas de evidencia — contó el encabezado dos veces. ¿Cuántas filas hay en realidad? (+5 XP) | D11: =IF(C11="","–",IF(IFERROR(VALUE(C11)='🔒 Clave'!B4,FALSE),"✓ +5 XP","✗ revisa")) -> – | E11: =IF(LEFT(D11,1)="✓",5,0) -> 0
A13: 🧹 SECCIÓN 2 — Limpiar el Caso (40 XP)
A14: Clave | B14: Instrucción | C14: Tu respuesta | D14: Resultado
A15: 🧹 LIMPIEZA — duplicados, texto inconsistente y vacíos
A16: Un duplicado exacto tiene el mismo Comprador, Boletos y Día repetidos dos veces.
A17: 'VIERNES' y 'viernes' significan lo mismo para una persona, pero no para una computadora — hay que escribirlo exactamente igual en toda la columna.
A18: Antes de asumir un valor vacío, investiga: pregunta, no adivines.
A19: 🔑 Duplicado exacto = mismo Comprador + mismo Boletos + mismo Día
A21: ex3 | B21: En 📊 Datos, pon en negrita la fila de encabezados y agrégale bordes. Marca la casilla cuando termines — tu profesor(a) revisa el formato. (+5 XP) | D21: =IF(C21=TRUE,"👀 revisión →","⏳ pendiente") -> ⏳ pendiente
A22: ex4 | B22: En 📊 Datos, elimina las filas duplicadas exactas Y las filas Canceladas. Al terminar deberían quedar exactamente 90 filas válidas. (+10 XP) | C22: — se revisa solo — | D22: =IF(AND(COUNTIF('📊 Datos'!D5:D112,"Cancelado")=0,COUNTA('📊 Datos'!A5:A112)=90),"✓ +10 XP","✗ revisa") -> ✗ revisa | E22: =IF(LEFT(D22,1)="✓",10,0) -> 0
A23: ex5 | B23: En 📊 Datos, estandariza la columna Día a exactamente 'Viernes' o 'Sábado' (sin mayúsculas irregulares tipo VIERNES, sábado, SABADO). (+10 XP) | C23: — se revisa solo — | D23: =IF(AND(COUNTA('📊 Datos'!A5:A112)=90,COUNTIF('📊 Datos'!C5:C112,"Viernes")+COUNTIF('📊 Datos'!C5:C112,"Sábado")=90),"✓ +10 XP","✗ revisa") -> ✗ revisa | E23: =IF(LEFT(D23,1)="✓",10,0) -> 0
A24: ex6 | B24: Nueva pista: la Agencia encontró los boletos que faltaban (ver la tabla de pistas más abajo). Complétalos en 📊 Datos. (+10 XP) | C24: — se revisa solo — | D24: =IF(AND(SUMPRODUCT(('📊 Datos'!A5:A112<>"")*('📊 Datos'!B5:B112=""))=0,SUM('📊 Datos'!B5:B112)=324),"✓ +10 XP","✗ revisa") -> ✗ revisa | E24: =IF(LEFT(D24,1)="✓",10,0) -> 0
A25: t2 | B25: Una celda de Boletos está vacía. ¿Qué deberías hacer? a) Borrar la fila, b) Asumir que es 0, c) Investigar antes de asumir, d) Poner el promedio del resto (+5 XP) | D25: =IF(C25="","–",IF(IFERROR(EXACT(LOWER(C25),LOWER('🔒 Clave'!B6)),FALSE),"✓ +5 XP","✗ revisa")) -> – | E25: =IF(LEFT(D25,1)="✓",5,0) -> 0
A26: check_mini_b | B26: 🔒 Checkpoint: completa ex4 + ex5 + ex6 + t2 antes de pasar a la Sección 3.
A28: 🕵️ Nueva pista — boletos que la Agencia encontró
A29: Comprador | B29: Boletos
A30: Gabriela Salas | B30: 5
A31: Camila Chumpitaz | B31: 2
A32: Lucía Ninahuanca | B32: 4
A33: Bruno Alania | B33: 2
A34: Sebastián Cusi | B34: 2
A35: Lucía Soto | B35: 2
A36: Fernando Alania | B36: 3
A37: María Palomino | B37: 3
A38: Lucía Mamani | B38: 2
A39: Jorge Palomino | B39: 2
A40: Luis Huamán | B40: 3
A41: Fernando Rojas | B41: 3
A43: — Fin de la Recepción y Limpieza —
A45: 🔍 SECCIÓN 3 — Filtrar por Día (35 XP)
A46: Clave | B46: Instrucción | C46: Tu respuesta | D46: Resultado
A47: 🔍 FILTRO — cómo verlo por partes
...

Sheet 🔒 Clave
A1: clave | B1: valor
A2: ex1 | B2: 108
A3: ex2 | B3: 4
A4: debug1 | B4: 108
A5: t1 | B5: b
A6: t2 | B6: c
A7: t3 | B7: b
A8: ex4_target_count | B8: 90
A9: ex6_target_sum | B9: 324
